Workbook

Sheet Datas
A1: LLM: gpt-oss
A3: Application | B3: Version | C3: Repository | D3: Testing repository | E3: Java | F3: Build command | G3: Repository size (MB) | H3: Apk size (MB) | I3: Kotlin Files Scanned | J3: Java Files Scanned | K3: Total Files Scanned | L3: LOC | M3: CodeQL Findings | N3: Semgrep Findings | O3: MobSF risk findings | P3: Files extracted by MobSF | Q3: Android components | R3: Exported Android components | S3: UFP (Unadjusted Function Points) | T3: Execution 1 | AH3: Execution 2 | AV3: Execution 3 | BJ3: Execution 4 | BX3: Execution 5 | CL3: Execution 6 | CZ3: Execution 7 | DN3: Execution 8 | EB3: Execution 9 | EP3: Execution 10 | FD3: Mean
T4: Total Time (s.) | U4: Compile Time (s.) | V4: Analysis Time (s.) | W4: CodeQL Analysis Time (s.) | X4: Trivi Scan Time (s.) | Y4: MobSF Time (s.) | Z4: MobSF Analysis Time (s.) | AA4: Vision360 generator (s.) | AB4: Evaluate security requirements (s.) | AC4: Generate structured JSON outpt (s.) | AD4: Total Generate final summary (s.) | AE4: Download and install OpenOffice (s.) | AF4: Generate final summary (s.) | AG4: Compliance summary | AH4: Total Time (s.) | AI4: Compile Time (s.) | AJ4: Analysis Time (s.) | AK4: CodeQL Analysis Time (s.) | AL4: Trivi Scan Time (s.) | AM4: MobSF Time (s.) | AN4: MobSF Analysis Time (s.) | AO4: Vision360 generator (s.) | AP4: Evaluate security requirements (s.) | AQ4: Generate structured JSON outpt (s.) | AR4: Total Generate final summary (s.) | AS4: Download and install OpenOffice (s.) | AT4: Generate final summary (s.) | AU4: Compliance summary | AV4: Total Time (s.) | AW4: Compile Time (s.) | AX4: Audit Time (s.) | AY4: CodeQL Analysis Time (s.) | AZ4: Trivi Scan Time (s.) | BA4: MobSF Time (s.) | BB4: MobSF Analysis Time (s.) | BC4: Vision360 generator (s.) | BD4: Evaluate security requirements (s.) | BE4: Generate structured JSON outpt (s.) | BF4: Total Generate final summary (s.) | BG4: Download and install OpenOffice (s.) | BH4: Generate final summary (s.) | BI4: Compliance summary | BJ4: Total Time (s.) | BK4: Compile Time (s.) | BL4: Audit Time (s.) | BM4: CodeQL Analysis Time (s.) | BN4: Trivi Scan Time (s.) | BO4: MobSF Time (s.) | BP4: MobSF Analysis Time (s.) | BQ4: Vision360 generator (s.) | BR4: Evaluate security requirements (s.) | BS4: Generate structured JSON outpt (s.) | BT4: Total Generate final summary (s.) | BU4: Download and install OpenOffice (s.) | BV4: Generate final summary (s.) | BW4: Compliance summary | BX4: Total Time (s.) | BY4: Compile Time (s.) | BZ4: Audit Time (s.) | CA4: CodeQL Analysis Time (s.) | CB4: Trivi Scan Time (s.) | CC4: MobSF Time (s.) | CD4: MobSF Analysis Time (s.) | CE4: Vision360 generator (s.) | CF4: Evaluate security requirements (s.) | CG4: Generate structured JSON outpt (s.) | CH4: Total Generate final summary (s.) | CI4: Download and install OpenOffice (s.) | CJ4: Generate final summary (s.) | CK4: Compliance summary | CL4: Total Time (s.) | CM4: Compile Time (s.) | CN4: Audit Time (s.) | CO4: CodeQL Analysis Time (s.) | CP4: Trivi Scan Time (s.) | CQ4: MobSF Time (s.) | CR4: MobSF Analysis Time (s.) | CS4: Vision360 generator (s.) | CT4: Evaluate security requirements (s.) | CU4: Generate structured JSON outpt (s.) | CV4: Total Generate final summary (s.) | CW4: Download and install OpenOffice (s.) | CX4: Generate final summary (s.) | CY4: Compliance summary | CZ4: Total Time (s.) | DA4: Compile Time (s.) | DB4: Audit Time (s.) | DC4: CodeQL Analysis Time (s.) | DD4: Trivi Scan Time (s.) | DE4: MobSF Time (s.) | DF4: MobSF Analysis Time (s.) | DG4: Vision360 generator (s.) | DH4: Evaluate security requirements (s.) | DI4: Generate structured JSON outpt (s.) | DJ4: Total Generate final summary (s.) | DK4: Download and install OpenOffice (s.) | DL4: Generate final summary (s.) | DM4: Compliance summary | DN4: Total Time (s.) | DO4: Compile Time (s.) | DP4: Audit Time (s.) | DQ4: CodeQL Analysis Time (s.) | DR4: Trivi Scan Time (s.) | DS4: MobSF Time (s.) | DT4: MobSF Analysis Time (s.) | DU4: Vision360 generator (s.) | DV4: Evaluate security requirements (s.) | DW4: Generate structured JSON outpt (s.) | DX4: Total Generate final summary (s.) | DY4: Download and install OpenOffice (s.) | DZ4: Generate final summary (s.) | EA4: Compliance summary | EB4: Total Time (s.) | EC4: Compile Time (s.) | ED4: Audit Time (s.) | EE4: CodeQL Analysis Time (s.) | EF4: Trivi Scan Time (s.) | EG4: MobSF Time (s.) | EH4: MobSF Analysis Time (s.) | EI4: Vision360 generator (s.) | EJ4: Evaluate security requirements (s.) | EK4: Generate structured JSON outpt (s.) | EL4: Total Generate final summary (s.) | EM4: Download and install OpenOffice (s.) | EN4: Generate final summary (s.) | EO4: Compliance summary | EP4: Total Time (s.) | EQ4: Compile Time (s.) | ER4: Audit Time (s.) | ES4: CodeQL Analysis Time (s.) | ET4: Trivi Scan Time (s.) | EU4: MobSF Time (s.) | EV4: MobSF Analysis Time (s.) | EW4: Vision360 generator (s.) | EX4: Evaluate security requirements (s.) | EY4: Generate structured JSON outpt (s.) | EZ4: Total Generate final summary (s.) | FA4: Download and install OpenOffice (s.) | FB4: Generate final summary (s.) | FC4: Compliance summary | FD4: Total Time (s.) | FE4: Compile Time (s.) | FF4: Audit Time (s.) | FG4: Compliance summary | FH4: MobSF Analisys | FI4: CodeQL Analisys | FJ4: Vision360 | FK4: Trivy Analisys | FL4: Final summary | FM4: JSON output | FN4: Req. Evaluation
A5: Signal Android | B5: 8.14.3 | C5: https://github.com/signalapp/Signal-Android | D5: https://github.com/investigaciongiis/test_signal_android | E5: 17 | F5: .\gradlew.bat --no-daemon clean :Signal-Android:assemblePlayProdRelease | G5: 2360 | H5: 240.472 | I5: 3551 | J5: 1772 | K5: 8737 | L5: 1603006 | M5: 1877 | N5: 88 | O5: 49 | P5: 4404 | Q5: 161 | R5: 29 | S5: 12500 | T5: 2124 | U5: 909 | V5: =T5-U5 -> 1215 | W5: 880 | X5: 246 | Y5: 1575 | Z5: =Y5-U5 -> 666 | AA5: 400 | AB5: 16 | AC5: 19 | AD5: 92 | AE5: 46 | AF5: =AD5-AE5 -> 46 | AG5: total=469 yes=51 no=358 n/a=60 | AH5: 1555 | AI5: 412 | AJ5: =AH5-AI5 -> 1143 | AK5: 879 | AL5: 245 | AM5: 916 | AN5: =AM5-AI5 -> 504 | AO5: 517 | AP5: 17 | AQ5: 19 | AR5: 68 | AS5: 30 | AT5: =AR5-AS5 -> 38 | AU5: total=469 yes=51 no=358 n/a=60 | AV5: 1897 | AW5: 762 | AX5: =AV5-AW5 -> 1135 | AY5: 887 | AZ5: 234 | BA5: 1262 | BB5: =BA5-AW5 -> 500 | BC5: 512 | BD5: 19 | BE5: 17 | BF5: 66 | BG5: 30 | BH5: =BF5-BG5 -> 36 | BI5: total=469 yes=51 no=358 n/a=60 | BJ5: 2288 | BK5: 878 | BL5: =BJ5-BK5 -> 1410 | BM5: 748 | BN5: 239 | BO5: 1656 | BP5: =BO5-BK5 -> 778 | BQ5: 508 | BR5: 16 | BS5: 22 | BT5: 69 | BU5: 40 | BV5: =BT5-BU5 -> 29 | BW5: total=469 yes=51 no=358 n/a=60 | BX5: 2144 | BY5: 862 | BZ5: =BX5-BY5 -> 1282 | CA5: 890 | CB5: 241 | CC5: 1481 | CD5: =CC5-BY5 -> 619 | CE5: 516 | CF5: 21 | CG5: 17 | CH5: 89 | CI5: 42 | CJ5: =CH5-CI5 -> 47 | CK5: total=469 yes=51 no=358 n/a=60 | CL5: 1577 | CM5: 407 | CN5: =CL5-CM5 -> 1170 | CO5: 869 | CP5: 221 | CQ5: 909 | CR5: =CQ5-CM5 -> 502 | CS5: 515 | CT5: 18 | CU5: 21 | CV5: 94 | CW5: 47 | CX5: =CV5-CW5 -> 47 | CY5: total=469 yes=51 no=358 n/a=60 | CZ5: 1600 | DA5: 409 | DB5: =CZ5-DA5 -> 1191 | DC5: 876 | DD5: 243 | DE5: 923 | DF5: =DE5-DA5 -> 514 | DG5: 530 | DH5: 22 | DI5: 23 | DJ5: 85 | DK5: 44 | DL5: =DJ5-DK5 -> 41 | DM5: total=469 yes=51 no=358 n/a=60 | DN5: 1583 | DO5: 407 | DP5: =DN5-DO5 -> 1176 | DQ5: 871 | DR5: 247 | DS5: 908 | DT5: =DS5-DO5 -> 501 | DU5: 525 | DV5: 19 | DW5: 21 | DX5: 86 | DY5: 51 | DZ5: =DX5-DY5 -> 35 | EA5: total=469 yes=51 no=358 n/a=60 | EB5: 1561 | EC5: 409 | ED5: =EB5-EC5 -> 1152 | EE5: 902 | EF5: 217 | EG5: 927 | EH5: =EG5-EC5 -> 518 | EI5: 518 | EJ5: 14 | EK5: 16 | EL5: 67 | EM5: 31 | EN5: =EL5-EM5 -> 36 | EO5: total=469 yes=51 no=358 n/a=60 | EP5: 1567 | EQ5: 411 | ER5: =EP5-EQ5 -> 1156 | ES5: 836 | ET5: 226 | EU5: 925 | EV5: =EU5-EQ5 -> 514 | EW5: 516 | EX5: 13 | EY5: 17 | EZ5: 74 | FA5: 35 | FB5: =EZ5-FA5 -> 39 | FC5: total=469 yes=51 no=358 n/a=60 | FD5: =AVERAGE(T5,AH5,AV5,BJ5,BX5,CL5,CZ5,DN5,EB5,EP5) -> 1789.6 | FE5: =AVERAGE(U5,AI5,AW5,BK5,BY5,CM5,DA5,DO5,EC5,EQ5) -> 586.6 | FF5: =AVERAGE(V5,AJ5,AX5,BL5,BZ5,CN5,DB5,DP5,ED5,ER5) -> 1203 | FG5: =IF(AND(FC5=EO5,FC5=EA5,FC5=DM5,FC5=CY5,FC5=CK5,FC5=BW5,FC5=BI5,FC5=AU5,FC5=AG5),"equal","no equal") -> equal | FH5: =AVERAGE(Z5,AN5,BB5,BP5,CD5,CR5,DF5,DT5,EH5,EV5) -> 561.6 | FI5: =AVERAGE(W5,AK5,AY5,BM5,CA5,CO5,DC5,DQ5,EE5,ES5) -> 863.8 | FJ5: =AVERAGE(AA5,AO5,BC5,BQ5,CE5,CS5,DG5,DU5,EI5,EW5) -> 505.7 | FK5: =AVERAGE(X5,AL5,AZ5,BN5,CB5,CP5,DD5,DR5,EF5,ET5) -> 235.9 | FL5: =AVERAGE(AD5,AR5,BF5,BT5,CH5,CV5,DJ5,DX5,EL5,EZ5) -> 79 | FM5: =AVERAGE(AC5,AQ5,BE5,BS5,CG5,CU5,DI5,DW5,EK5,EY5) -> 19.2 | FN5: =AVERAGE(AB5,AP5,BD5,BR5,CF5,CT5,DH5,DV5,EJ5,EX5) -> 17.5
A6: K-9 Mail (Thunderbird Android) | B6: 19.2 | C6: https://github.com/thunderbird/thunderbird-android | D6: https://github.com/investigaciongiis/test_k9_mail | E6: 21 | F6: .\gradlew.bat --no-daemon clean :app-thunderbird:assembleRelease | G6: 248 | H6: 10.6 | I6: 2807 | J6: 239 | K6: 7139 | L6: 129770 | M6: 295 | N6: 44 | O6: 28 | P6: 1128 | Q6: 18 | R6: 13 | S6: 1183 | T6: 887 | U6: 179 | V6: =T6-U6 -> 708 | W6: 302 | X6: 291 | Y6: 350 | Z6: =Y6-U6 -> 171 | AA6: 382 | AB6: 16 | AC6: 21 | AD6: 97 | AE6: 54 | AF6: =AD6-AE6 -> 43 | AG6: total=469 yes=22 no=388 n/a=59 | AH6: 878 | AI6: 163 | AJ6: =AH6-AI6 -> 715 | AK6: 312 | AL6: 322 | AM6: 332 | AN6: =AM6-AI6 -> 169 | AO6: 428 | AP6: 14 | AQ6: 15 | AR6: 68 | AS6: 33 | AT6: =AR6-AS6 -> 35 | AU6: total=469 yes=22 no=388 n/a=59 | AV6: 840 | AW6: 162 | AX6: =AV6-AW6 -> 678 | AY6: 290 | AZ6: 274 | BA6: 336 | BB6: =BA6-AW6 -> 174 | BC6: 383 | BD6: 18 | BE6: 21 | BF6: 71 | BG6: 34 | BH6: =BF6-BG6 -> 37 | BI6: total=469 yes=22 no=388 n/a=59 | BJ6: 926 | BK6: 165 | BL6: =BJ6-BK6 -> 761 | BM6: 280 | BN6: 268 | BO6: 332 | BP6: =BO6-BK6 -> 167 | BQ6: 434 | BR6: 28 | BS6: 21 | BT6: 88 | BU6: 48 | BV6: =BT6-BU6 -> 40 | BW6: total=469 yes=22 no=388 n/a=59 | BX6: 875 | BY6: 162 | BZ6: =BX6-BY6 -> 713 | CA6: 321 | CB6: 275 | CC6: 332 | CD6: =CC6-BY6 -> 170 | CE6: 397 | CF6: 19 | CG6: 20 | CH6: 88 | CI6: 37 | CJ6: =CH6-CI6 -> 51 | CK6: total=469 yes=22 no=388 n/a=59 | CL6: 897 | CM6: 162 | CN6: =CL6-CM6 -> 735 | CO6: 278 | CP6: 288 | CQ6: 334 | CR6: =CQ6-CM6 -> 172 | CS6: 418 | CT6: 19 | CU6: 17 | CV6: 89 | CW6: 46 | CX6: =CV6-CW6 -> 43 | CY6: total=469 yes=22 no=388 n/a=59 | CZ6: 889 | DA6: 161 | DB6: =CZ6-DA6 -> 728 | DC6: 315 | DD6: 244 | DE6: 332 | DF6: =DE6-DA6 -> 171 | DG6: 415 | DH6: 20 | DI6: 19 | DJ6: 84 | DK6: 44 | DL6: =DJ6-DK6 -> 40 | DM6: total=469 yes=22 no=388 n/a=59 | DN6: 858 | DO6: 160 | DP6: =DN6-DO6 -> 698 | DQ6: 232 | DR6: 299 | DS6: 328 | DT6: =DS6-DO6 -> 168 | DU6: 407 | DV6: 23 | DW6: 16 | DX6: 66 | DY6: 31 | DZ6: =DX6-DY6 -> 35 | EA6: total=469 yes=22 no=388 n/a=59 | EB6: 878 | EC6: 160 | ED6: =EB6-EC6 -> 718 | EE6: 268 | EF6: 267 | EG6: 334 | EH6: =EG6-EC6 -> 174 | EI6: 422 | EJ6: 12 | EK6: 20 | EL6: 73 | EM6: 37 | EN6: =EL6-EM6 -> 36 | EO6: total=469 yes=22 no=388 n/a=59 | EP6: 916 | EQ6: 160 | ER6: =EP6-EQ6 -> 756 | ES6: 293 | ET6: 258 | EU6: 336 | EV6: =EU6-EQ6 -> 176 | EW6: 414 | EX6: 19 | EY6: 22 | EZ6: 92 | FA6: 43 | FB6: =EZ6-FA6 -> 49 | FC6: total=469 yes=22 no=388 n/a=59 | FD6: =AVERAGE(T6,AH6,AV6,BJ6,BX6,CL6,CZ6,DN6,EB6,EP6) -> 884.4 | FE6: =AVERAGE(U6,AI6,AW6,BK6,BY6,CM6,DA6,DO6,EC6,EQ6) -> 163.4 | FF6: =AVERAGE(V6,AJ6,AX6,BL6,BZ6,CN6,DB6,DP6,ED6,ER6) -> 721 | FG6: =IF(AND(FC6=EO6,FC6=EA6,FC6=DM6,FC6=CY6,FC6=CK6,FC6=BW6,FC6=BI6,FC6=AU6,FC6=AG6),"equal","no equal") -> equal | FH6: =AVERAGE(Z6,AN6,BB6,BP6,CD6,CR6,DF6,DT6,EH6,EV6) -> 171.2 | FI6: =AVERAGE(W6,AK6,AY6,BM6,CA6,CO6,DC6,DQ6,EE6,ES6) -> 289.1 | FJ6: =AVERAGE(AA6,AO6,BC6,BQ6,CE6,CS6,DG6,DU6,EI6,EW6) -> 410 | FK6: =AVERAGE(X6,AL6,AZ6,BN6,CB6,CP6,DD6,DR6,EF6,ET6) -> 278.6 | FL6: =AVERAGE(AD6,AR6,BF6,BT6,CH6,CV6,DJ6,DX6,EL6,EZ6) -> 81.6 | FM6: =AVERAGE(AC6,AQ6,BE6,BS6,CG6,CU6,DI6,DW6,EK6,EY6) -> 19.2 | FN6: =AVERAGE(AB6,AP6,BD6,BR6,CF6,CT6,DH6,DV6,EJ6,EX6) -> 18.8
A7: AntennaPod | B7: 3.11.4 | C7: https://github.com/AntennaPod/AntennaPod | D7: https://github.com/investigaciongiis/test_AntennaPod | E7: 21 | F7: .\gradlew.bat --no-daemon clean :app:assemblePlayRelease | G7: 134 | H7: 10.1 | I7: 14 | J7: 537 | K7: 1165 | L7: 62675 | M7: 619 | N7: 21 | O7: 38 | P7: 2180 | Q7: 46 | R7: 19 | S7: 1180 | T7: 566 | U7: 276 | V7: =T7-U7 -> 290 | W7: 366 | X7: 110 | Y7: 411 | Z7: =Y7-U7 -> 135 | AA7: 29 | AB7: 13 | AC7: 16 | AD7: 79 | AE7: 38 | AF7: =AD7-AE7 -> 41 | AG7: total=469 yes=26 no=379 n/a=64 | AH7: 573 | AI7: 271 | AJ7: =AH7-AI7 -> 302 | AK7: 414 | AL7: 113 | AM7: 406 | AN7: =AM7-AI7 -> 135 | AO7: 22 | AP7: 16 | AQ7: 18 | AR7: 85 | AS7: 39 | AT7: =AR7-AS7 -> 46 | AU7: total=469 yes=26 no=379 n/a=64 | AV7: 563 | AW7: 271 | AX7: =AV7-AW7 -> 292 | AY7: 370 | AZ7: 99 | BA7: 403 | BB7: =BA7-AW7 -> 132 | BC7: 28 | BD7: 12 | BE7: 20 | BF7: 81 | BG7: 32 | BH7: =BF7-BG7 -> 49 | BI7: total=469 yes=26 no=379 n/a=64 | BJ7: 548 | BK7: 276 | BL7: =BJ7-BK7 -> 272 | BM7: 351 | BN7: 105 | BO7: 410 | BP7: =BO7-BK7 -> 134 | BQ7: 29 | BR7: 14 | BS7: 15 | BT7: 62 | BU7: 31 | BV7: =BT7-BU7 -> 31 | BW7: total=469 yes=26 no=379 n/a=64 | BX7: 577 | BY7: 270 | BZ7: =BX7-BY7 -> 307 | CA7: 413 | CB7: 113 | CC7: 404 | CD7: =CC7-BY7 -> 134 | CE7: 24 | CF7: 18 | CG7: 25 | CH7: 76 | CI7: 37 | CJ7: =CH7-CI7 -> 39 | CK7: total=469 yes=26 no=379 n/a=64 | CL7: 593 | CM7: 274 | CN7: =CL7-CM7 -> 319 | CO7: 375 | CP7: 102 | CQ7: 413 | CR7: =CQ7-CM7 -> 139 | CS7: 24 | CT7: 16 | CU7: 19 | CV7: 98 | CW7: 35 | CX7: =CV7-CW7 -> 63 | CY7: total=469 yes=26 no=379 n/a=64 | CZ7: 552 | DA7: 272 | DB7: =CZ7-DA7 -> 280 | DC7: 357 | DD7: 108 | DE7: 406 | DF7: =DE7-DA7 -> 134 | DG7: 28 | DH7: 14 | DI7: 22 | DJ7: 64 | DK7: 33 | DL7: =DJ7-DK7 -> 31 | DM7: total=469 yes=26 no=379 n/a=64 | DN7: 573 | DO7: 268 | DP7: =DN7-DO7 -> 305 | DQ7: 374 | DR7: 97 | DS7: 404 | DT7: =DS7-DO7 -> 136 | DU7: 22 | DV7: 14 | DW7: 21 | DX7: 91 | DY7: 47 | DZ7: =DX7-DY7 -> 44 | EA7: total=469 yes=26 no=379 n/a=64 | EB7: 649 | EC7: 350 | ED7: =EB7-EC7 -> 299 | EE7: 411 | EF7: 111 | EG7: 492 | EH7: =EG7-EC7 -> 142 | EI7: 31 | EJ7: 16 | EK7: 21 | EL7: 67 | EM7: 35 | EN7: =EL7-EM7 -> 32 | EO7: total=469 yes=26 no=379 n/a=64 | EP7: 562 | EQ7: 272 | ER7: =EP7-EQ7 -> 290 | ES7: 360 | ET7: 110 | EU7: 405 | EV7: =EU7-EQ7 -> 133 | EW7: 26 | EX7: 14 | EY7: 18 | EZ7: 80 | FA7: 38 | FB7: =EZ7-FA7 -> 42 | FC7: total=469 yes=26 no=379 n/a=64 | FD7: =AVERAGE(T7,AH7,AV7,BJ7,BX7,CL7,CZ7,DN7,EB7,EP7) -> 575.6 | FE7: =AVERAGE(U7,AI7,AW7,BK7,BY7,CM7,DA7,DO7,EC7,EQ7) -> 280 | FF7: =AVERAGE(V7,AJ7,AX7,BL7,BZ7,CN7,DB7,DP7,ED7,ER7) -> 295.6 | FG7: =IF(AND(FC7=EO7,FC7=EA7,FC7=DM7,FC7=CY7,FC7=CK7,FC7=BW7,FC7=BI7,FC7=AU7,FC7=AG7),"equal","no equal") -> equal | FH7: =AVERAGE(Z7,AN7,BB7,BP7,CD7,CR7,DF7,DT7,EH7,EV7) -> 135.4 | FI7: =AVERAGE(W7,AK7,AY7,BM7,CA7,CO7,DC7,DQ7,EE7,ES7) -> 379.1 | FJ7: =AVERAGE(AA7,AO7,BC7,BQ7,CE7,CS7,DG7,DU7,EI7,EW7) -> 26.3 | FK7: =AVERAGE(X7,AL7,AZ7,BN7,CB7,CP7,DD7,DR7,EF7,ET7) -> 106.8 | FL7: =AVERAGE(AD7,AR7,BF7,BT7,CH7,CV7,DJ7,DX7,EL7,EZ7) -> 78.3 | FM7: =AVERAGE(AC7,AQ7,BE7,BS7,CG7,CU7,DI7,DW7,EK7,EY7) -> 19.5 | FN7: =AVERAGE(AB7,AP7,BD7,BR7,CF7,CT7,DH7,DV7,EJ7,EX7) -> 14.7
A8: Markor | B8: 2.16.1 | C8: https://github.com/gsantner/markor | D8: https://github.com/investigaciongiis/test_markor | E8: 21 | F8: .\gradlew.bat --no-daemon clean :app:assembleFlavorGplayRelease | G8: 58.2 | H8: 11.3 | I8: 0 | J8: 140 | K8: 797 | L8: 30512 | M8: 158 | N8: 15 | O8: 19 | P8: 2526 | Q8: 17 | R8: 8 | S8: 576 | T8: 406 | U8: 142 | V8: =T8-U8 -> 264 | W8: 263 | X8: 83 | Y8: 255 | Z8: =Y8-U8 -> 113 | AA8: 18 | AB8: 16 | AC8: 19 | AD8: 70 | AE8: 33 | AF8: =AD8-AE8 -> 37 | AG8: total=469 yes=22 no=388 n/a=59 | AH8: 388 | AI8: 132 | AJ8: =AH8-AI8 -> 256 | AK8: 250 | AL8: 80 | AM8: 246 | AN8: =AM8-AI8 -> 114 | AO8: 21 | AP8: 15 | AQ8: 18 | AR8: 63 | AS8: 32 | AT8: =AR8-AS8 -> 31 | AU8: total=469 yes=22 no=388 n/a=59 | AV8: 564 | AW8: 141 | AX8: =AV8-AW8 -> 423 | AY8: 249 | AZ8: 92 | BA8: 251 | BB8: =BA8-AW8 -> 110 | BC8: 19 | BD8: 16 | BE8: 21 | BF8: 218 | BG8: 176 | BH8: =BF8-BG8 -> 42 | BI8: total=469 yes=22 no=388 n/a=59 | BJ8: 423 | BK8: 136 | BL8: =BJ8-BK8 -> 287 | BM8: 265 | BN8: 141 | BO8: 249 | BP8: =BO8-BK8 -> 113 | BQ8: 14 | BR8: 18 | BS8: 19 | BT8: 87 | BU8: 46 | BV8: =BT8-BU8 -> 41 | BW8: total=469 yes=22 no=388 n/a=59 | BX8: 420 | BY8: 131 | BZ8: =BX8-BY8 -> 289 | CA8: 252 | CB8: 101 | CC8: 245 | CD8: =CC8-BY8 -> 114 | CE8: 20 | CF8: 16 | CG8: 17 | CH8: 93 | CI8: 44 | CJ8: =CH8-CI8 -> 49 | CK8: total=469 yes=22 no=388 n/a=59 | CL8: 429 | CM8: 133 | CN8: =CL8-CM8 -> 296 | CO8: 268 | CP8: 90 | CQ8: 247 | CR8: =CQ8-CM8 -> 114 | CS8: 27 | CT8: 19 | CU8: 23 | CV8: 69 | CW8: 34 | CX8: =CV8-CW8 -> 35 | CY8: total=469 yes=22 no=388 n/a=59 | CZ8: 440 | DA8: 138 | DB8: =CZ8-DA8 -> 302 | DC8: 272 | DD8: 82 | DE8: 253 | DF8: =DE8-DA8 -> 115 | DG8: 24 | DH8: 13 | DI8: 21 | DJ8: 87 | DK8: 40 | DL8: =DJ8-DK8 -> 47 | DM8: total=469 yes=22 no=388 n/a=59 | DN8: 415 | DO8: 142 | DP8: =DN8-DO8 -> 273 | DQ8: 260 | DR8: 87 | DS8: 256 | DT8: =DS8-DO8 -> 114 | DU8: 16 | DV8: 11 | DW8: 19 | DX8: 85 | DY8: 45 | DZ8: =DX8-DY8 -> 40 | EA8: total=469 yes=22 no=388 n/a=59 | EB8: 471 | EC8: 141 | ED8: =EB8-EC8 -> 330 | EE8: 298 | EF8: 87 | EG8: 255 | EH8: =EG8-EC8 -> 114 | EI8: 20 | EJ8: 16 | EK8: 16 | EL8: 73 | EM8: 31 | EN8: =EL8-EM8 -> 42 | EO8: total=469 yes=22 no=388 n/a=59 | EP8: 416 | EQ8: 136 | ER8: =EP8-EQ8 -> 280 | ES8: 254 | ET8: 112 | EU8: 259 | EV8: =EU8-EQ8 -> 123 | EW8: 15 | EX8: 15 | EY8: 18 | EZ8: 87 | FA8: 53 | FB8: =EZ8-FA8 -> 34 | FC8: total=469 yes=22 no=388 n/a=59 | FD8: =AVERAGE(T8,AH8,AV8,BJ8,BX8,CL8,CZ8,DN8,EB8,EP8) -> 437.2 | FE8: =AVERAGE(U8,AI8,AW8,BK8,BY8,CM8,DA8,DO8,EC8,EQ8) -> 137.2 | FF8: =AVERAGE(V8,AJ8,AX8,BL8,BZ8,CN8,DB8,DP8,ED8,ER8) -> 300 | FG8: =IF(AND(FC8=EO8,FC8=EA8,FC8=DM8,FC8=CY8,FC8=CK8,FC8=BW8,FC8=BI8,FC8=AU8,FC8=AG8),"equal","no equal") -> equal | FH8: =AVERAGE(Z8,AN8,BB8,BP8,CD8,CR8,DF8,DT8,EH8,EV8) -> 114.4 | FI8: =AVERAGE(W8,AK8,AY8,BM8,CA8,CO8,DC8,DQ8,EE8,ES8) -> 263.1 | FJ8: =AVERAGE(AA8,AO8,BC8,BQ8,CE8,CS8,DG8,DU8,EI8,EW8) -> 19.4 | FK8: =AVERAGE(X8,AL8,AZ8,BN8,CB8,CP8,DD8,DR8,EF8,ET8) -> 95.5 | FL8: =AVERAGE(AD8,AR8,BF8,BT8,CH8,CV8,DJ8,DX8,EL8,EZ8) -> 93.2 | FM8: =AVERAGE(AC8,AQ8,BE8,BS8,CG8,CU8,DI8,DW8,EK8,EY8) -> 19.1 | FN8: =AVERAGE(AB8,AP8,BD8,BR8,CF8,CT8,DH8,DV8,EJ8,EX8) -> 15.5
A9: Fdroidclient | B9: 1.18.0 | C9: https://github.com/f-droid/fdroidclient | D9: https://github.com/investigaciongiis/test_fdroidclient | E9: 17 | F9: .\gradlew.bat --no-daemon clean assembleRelease | G9: 79.7 | H9: 11.9 | I9: 118 | J9: 232 | K9: 2086 | L9: 94671 | M9: 235 | N9: 31 | O9: 22 | P9: 1220 | Q9: 18 | R9: 9 | S9: 716 | T9: 471 | U9: 127 | V9: =T9-U9 -> 344 | W9: 307 | X9: 85 | Y9: 316 | Z9: =Y9-U9 -> 189 | AA9: 32 | AB9: 15 | AC9: 15 | AD9: 70 | AE9: 34 | AF9: =AD9-AE9 -> 36 | AG9: total=469 yes=37 no=367 n/a=65 | AH9: 484 | AI9: 124 | AJ9: =AH9-AI9 -> 360 | AK9: 291 | AL9: 83 | AM9: 316 | AN9: =AM9-AI9 -> 192 | AO9: 37 | AP9: 12 | AQ9: 21 | AR9: 73 | AS9: 38 | AT9: =AR9-AS9 -> 35 | AU9: total=469 yes=37 no=367 n/a=65 | AV9: 499 | AW9: 123 | AX9: =AV9-AW9 -> 376 | AY9: 304 | AZ9: 98 | BA9: 312 | BB9: =BA9-AW9 -> 189 | BC9: 58 | BD9: 16 | BE9: 23 | BF9: 70 | BG9: 35 | BH9: =BF9-BG9 -> 35 | BI9: total=469 yes=37 no=367 n/a=65 | BJ9: 612 | BK9: 125 | BL9: =BJ9-BK9 -> 487 | BM9: 292 | BN9: 98 | BO9: 314 | BP9: =BO9-BK9 -> 189 | BQ9: 35 | BR9: 18 | BS9: 16 | BT9: 209 | BU9: 175 | BV9: =BT9-BU9 -> 34 | BW9: total=469 yes=37 no=367 n/a=65 | BX9: 533 | BY9: 124 | BZ9: =BX9-BY9 -> 409 | CA9: 335 | CB9: 89 | CC9: 313 | CD9: =CC9-BY9 -> 189 | CE9: 40 | CF9: 19 | CG9: 21 | CH9: 84 | CI9: 43 | CJ9: =CH9-CI9 -> 41 | CK9: total=469 yes=37 no=367 n/a=65 | CL9: 492 | CM9: 123 | CN9: =CL9-CM9 -> 369 | CO9: 302 | CP9: 87 | CQ9: 317 | CR9: =CQ9-CM9 -> 194 | CS9: 32 | CT9: 17 | CU9: 22 | CV9: 76 | CW9: 38 | CX9: =CV9-CW9 -> 38 | CY9: total=469 yes=37 no=367 n/a=65 | CZ9: 685 | DA9: 334 | DB9: =CZ9-DA9 -> 351 | DC9: 308 | DD9: 105 | DE9: 523 | DF9: =DE9-DA9 -> 189 | DG9: 33 | DH9: 18 | DI9: 20 | DJ9: 74 | DK9: 38 | DL9: =DJ9-DK9 -> 36 | DM9: total=469 yes=37 no=367 n/a=65 | DN9: 436 | DO9: 122 | DP9: =DN9-DO9 -> 314 | DQ9: 278 | DR9: 91 | DS9: 274 | DT9: =DS9-DO9 -> 152 | DU9: 39 | DV9: 13 | DW9: 21 | DX9: 67 | DY9: 30 | DZ9: =DX9-DY9 -> 37 | EA9: total=469 yes=37 no=367 n/a=65 | EB9: 525 | EC9: 124 | ED9: =EB9-EC9 -> 401 | EE9: 353 | EF9: 94 | EG9: 279 | EH9: =EG9-EC9 -> 155 | EI9: 34 | EJ9: 13 | EK9: 15 | EL9: 91 | EM9: 45 | EN9: =EL9-EM9 -> 46 | EO9: total=469 yes=37 no=367 n/a=65 | EP9: 672 | EQ9: 321 | ER9: =EP9-EQ9 -> 351 | ES9: 334 | ET9: 104 | EU9: 509 | EV9: =EU9-EQ9 -> 188 | EW9: 36 | EX9: 15 | EY9: 18 | EZ9: 75 | FA9: 34 | FB9: =EZ9-FA9 -> 41 | FC9: total=469 yes=37 no=367 n/a=65 | FD9: =AVERAGE(T9,AH9,AV9,BJ9,BX9,CL9,CZ9,DN9,EB9,EP9) -> 540.9 | FE9: =AVERAGE(U9,AI9,AW9,BK9,BY9,CM9,DA9,DO9,EC9,EQ9) -> 164.7 | FF9: =AVERAGE(V9,AJ9,AX9,BL9,BZ9,CN9,DB9,DP9,ED9,ER9) -> 376.2 | FG9: =IF(AND(FC9=EO9,FC9=EA9,FC9=DM9,FC9=CY9,FC9=CK9,FC9=BW9,FC9=BI9,FC9=AU9,FC9=AG9),"equal","no equal") -> equal | FH9: =AVERAGE(Z9,AN9,BB9,BP9,CD9,CR9,DF9,DT9,EH9,EV9) -> 182.6 | FI9: =AVERAGE(W9,AK9,AY9,BM9,CA9,CO9,DC9,DQ9,EE9,ES9) -> 310.4 | FJ9: =AVERAGE(AA9,AO9,BC9,BQ9,CE9,CS9,DG9,DU9,EI9,EW9) -> 37.6 | FK9: =AVERAGE(X9,AL9,AZ9,BN9,CB9,CP9,DD9,DR9,EF9,ET9) -> 93.4 | FL9: =AVERAGE(AD9,AR9,BF9,BT9,CH9,CV9,DJ9,DX9,EL9,EZ9) -> 88.9 | FM9: =AVERAGE(AC9,AQ9,BE9,BS9,CG9,CU9,DI9,DW9,EK9,EY9) -> 19.2 | FN9: =AVERAGE(AB9,AP9,BD9,BR9,CF9,CT9,DH9,DV9,EJ9,EX9) -> 15.6
A10: Damn-Vulnerable-Android-Components | B10: 1 | C10: https://github.com/zinja-coder/Damn-Vulnerable-Android-Components | D10: https://github.com/investigaciongiis/test_dvac | E10: 21 | F10: .\gradlew.bat --no-daemon clean assembleRelease | G10: 37.3 | H10: 10.3 | I10: 0 | J10: 27 | K10: 120 | L10: 2854 | M10: 28 | N10: 11 | O10: 21 | P10: 857 | Q10: 18 | R10: 9 | S10: 79 | T10: 401 | U10: 51 | V10: =T10-U10 -> 350 | W10: 267 | X10: 97 | Y10: 150 | Z10: =Y10-U10 -> 99 | AA10: 11 | AB10: 11 | AC10: 14 | AD10: 79 | AE10: 38 | AF10: =AD10-AE10 -> 41 | AG10: total=469 yes=28 no=382 n/a=59 | AH10: 372 | AI10: 32 | AJ10: =AH10-AI10 -> 340 | AK10: 237 | AL10: 115 | AM10: 120 | AN10: =AM10-AI10 -> 88 | AO10: 11 | AP10: 16 | AQ10: 22 | AR10: 67 | AS10: 32 | AT10: =AR10-AS10 -> 35 | AU10: total=469 yes=28 no=382 n/a=59 | AV10: 396 | AW10: 36 | AX10: =AV10-AW10 -> 360 | AY10: 263 | AZ10: 106 | BA10: 124 | BB10: =BA10-AW10 -> 88 | BC10: 12 | BD10: 19 | BE10: 15 | BF10: 65 | BG10: 32 | BH10: =BF10-BG10 -> 33 | BI10: total=469 yes=28 no=382 n/a=59 | BJ10: 419 | BK10: 37 | BL10: =BJ10-BK10 -> 382 | BM10: 256 | BN10: 105 | BO10: 126 | BP10: =BO10-BK10 -> 89 | BQ10: 12 | BR10: 17 | BS10: 18 | BT10: 98 | BU10: 36 | BV10: =BT10-BU10 -> 62 | BW10: total=469 yes=28 no=382 n/a=59 | BX10: 387 | BY10: 34 | BZ10: =BX10-BY10 -> 353 | CA10: 232 | CB10: 104 | CC10: 124 | CD10: =CC10-BY10 -> 90 | CE10: 7 | CF10: 18 | CG10: 15 | CH10: 80 | CI10: 40 | CJ10: =CH10-CI10 -> 40 | CK10: total=469 yes=28 no=382 n/a=59 | CL10: 414 | CM10: 34 | CN10: =CL10-CM10 -> 380 | CO10: 270 | CP10: 100 | CQ10: 123 | CR10: =CQ10-CM10 -> 89 | CS10: 8 | CT10: 19 | CU10: 16 | CV10: 83 | CW10: 46 | CX10: =CV10-CW10 -> 37 | CY10: total=469 yes=28 no=382 n/a=59 | CZ10: 389 | DA10: 34 | DB10: =CZ10-DA10 -> 355 | DC10: 271 | DD10: 109 | DE10: 122 | DF10: =DE10-DA10 -> 88 | DG10: 8 | DH10: 12 | DI10: 15 | DJ10: 63 | DK10: 30 | DL10: =DJ10-DK10 -> 33 | DM10: total=469 yes=28 no=382 n/a=59 | DN10: 418 | DO10: 36 | DP10: =DN10-DO10 -> 382 | DQ10: 268 | DR10: 89 | DS10: 124 | DT10: =DS10-DO10 -> 88 | DU10: 8 | DV10: 16 | DW10: 16 | DX10: 88 | DY10: 45 | DZ10: =DX10-DY10 -> 43 | EA10: total=469 yes=28 no=382 n/a=59 | EB10: 439 | EC10: 36 | ED10: =EB10-EC10 -> 403 | EE10: 271 | EF10: 94 | EG10: 124 | EH10: =EG10-EC10 -> 88 | EI10: 12 | EJ10: 12 | EK10: 21 | EL10: 99 | EM10: 56 | EN10: =EL10-EM10 -> 43 | EO10: total=469 yes=28 no=382 n/a=59 | EP10: 434 | EQ10: 35 | ER10: =EP10-EQ10 -> 399 | ES10: 278 | ET10: 95 | EU10: 129 | EV10: =EU10-EQ10 -> 94 | EW10: 6 | EX10: 12 | EY10: 21 | EZ10: 97 | FA10: 65 | FB10: =EZ10-FA10 -> 32 | FC10: total=469 yes=28 no=382 n/a=59 | FD10: =AVERAGE(T10,AH10,AV10,BJ10,BX10,CL10,CZ10,DN10,EB10,EP10) -> 406.9 | FE10: =AVERAGE(U10,AI10,AW10,BK10,BY10,CM10,DA10,DO10,EC10,EQ10) -> 36.5 | FF10: =AVERAGE(V10,AJ10,AX10,BL10,BZ10,CN10,DB10,DP10,ED10,ER10) -> 370.4 | FG10: =IF(AND(FC10=EO10,FC10=EA10,FC10=DM10,FC10=CY10,FC10=CK10,FC10=BW10,FC10=BI10,FC10=AU10,FC10=AG10),"equal","no equal") -> equal | FH10: =AVERAGE(Z10,AN10,BB10,BP10,CD10,CR10,DF10,DT10,EH10,EV10) -> 90.1 | FI10: =AVERAGE(W10,AK10,AY10,BM10,CA10,CO10,DC10,DQ10,EE10,ES10) -> 261.3 | FJ10: =AVERAGE(AA10,AO10,BC10,BQ10,CE10,CS10,DG10,DU10,EI10,EW10) -> 9.5 | FK10: =AVERAGE(X10,AL10,AZ10,BN10,CB10,CP10,DD10,DR10,EF10,ET10) -> 101.4 | FL10: =AVERAGE(AD10,AR10,BF10,BT10,CH10,CV10,DJ10,DX10,EL10,EZ10) -> 81.9 | FM10: =AVERAGE(AC10,AQ10,BE10,BS10,CG10,CU10,DI10,DW10,EK10,EY10) -> 17.3 | FN10: =AVERAGE(AB10,AP10,BD10,BR10,CF10,CT10,DH10,DV10,EJ10,EX10) -> 15.2
A11: OpenMRS | B11: 3.1.1 | C11: https://github.com/investigaciongiis/openMRS | D11: https://github.com/investigaciongiis/test_openMRS | E11: 11 | F11: .\gradlew.bat --no-daemon clean assembleRelease | G11: 12.1 | H11: 11 | I11: 256 | J11: 64 | K11: 839 | L11: 53765 | M11: 75 | N11: 7 | O11: 14 | P11: 2909 | Q11: 49 | R11: 4 | S11: 462 | T11: 428 | U11: 164 | V11: =T11-U11 -> 264 | W11: 285 | X11: 95 | Y11: 296 | Z11: =Y11-U11 -> 132 | AA11: 14 | AB11: 11 | AC11: 17 | AD11: 70 | AE11: 34 | AF11: =AD11-AE11 -> 36 | AG11: total=469 yes=31 no=373 n/a=65 | AH11: 409 | AI11: 119 | AJ11: =AH11-AI11 -> 290 | AK11: 268 | AL11: 94 | AM11: 244 | AN11: =AM11-AI11 -> 125 | AO11: 17 | AP11: 14 | AQ11: 20 | AR11: 67 | AS11: 32 | AT11: =AR11-AS11 -> 35 | AU11: total=469 yes=31 no=373 n/a=65 | AV11: 407 | AW11: 119 | AX11: =AV11-AW11 -> 288 | AY11: 260 | AZ11: 96 | BA11: 243 | BB11: =BA11-AW11 -> 124 | BC11: 18 | BD11: 13 | BE11: 20 | BF11: 75 | BG11: 40 | BH11: =BF11-BG11 -> 35 | BI11: total=469 yes=31 no=373 n/a=65 | BJ11: 402 | BK11: 120 | BL11: =BJ11-BK11 -> 282 | BM11: 259 | BN11: 73 | BO11: 246 | BP11: =BO11-BK11 -> 126 | BQ11: 18 | BR11: 16 | BS11: 14 | BT11: 74 | BU11: 35 | BV11: =BT11-BU11 -> 39 | BW11: total=469 yes=31 no=373 n/a=65 | BX11: 388 | BY11: 119 | BZ11: =BX11-BY11 -> 269 | CA11: 252 | CB11: 77 | CC11: 244 | CD11: =CC11-BY11 -> 125 | CE11: 11 | CF11: 13 | CG11: 19 | CH11: 71 | CI11: 37 | CJ11: =CH11-CI11 -> 34 | CK11: total=469 yes=31 no=373 n/a=65 | CL11: 426 | CM11: 123 | CN11: =CL11-CM11 -> 303 | CO11: 256 | CP11: 81 | CQ11: 247 | CR11: =CQ11-CM11 -> 124 | CS11: 13 | CT11: 16 | CU11: 19 | CV11: 99 | CW11: 37 | CX11: =CV11-CW11 -> 62 | CY11: total=469 yes=31 no=373 n/a=65 | CZ11: 414 | DA11: 117 | DB11: =CZ11-DA11 -> 297 | DC11: 276 | DD11: 86 | DE11: 242 | DF11: =DE11-DA11 -> 125 | DG11: 13 | DH11: 11 | DI11: 21 | DJ11: 71 | DK11: 35 | DL11: =DJ11-DK11 -> 36 | DM11: total=469 yes=31 no=373 n/a=65 | DN11: 499 | DO11: 118 | DP11: =DN11-DO11 -> 381 | DQ11: 338 | DR11: 85 | DS11: 244 | DT11: =DS11-DO11 -> 126 | DU11: 17 | DV11: 16 | DW11: 16 | DX11: 85 | DY11: 44 | DZ11: =DX11-DY11 -> 41 | EA11: total=469 yes=31 no=373 n/a=65 | EB11: 385 | EC11: 119 | ED11: =EB11-EC11 -> 266 | EE11: 258 | EF11: 83 | EG11: 247 | EH11: =EG11-EC11 -> 128 | EI11: 14 | EJ11: 12 | EK11: 16 | EL11: 64 | EM11: 30 | EN11: =EL11-EM11 -> 34 | EO11: total=469 yes=31 no=373 n/a=65 | EP11: 440 | EQ11: 121 | ER11: =EP11-EQ11 -> 319 | ES11: 295 | ET11: 100 | EU11: 246 | EV11: =EU11-EQ11 -> 125 | EW11: 13 | EX11: 12 | EY11: 16 | EZ11: 84 | FA11: 39 | FB11: =EZ11-FA11 -> 45 | FC11: total=469 yes=31 no=373 n/a=65 | FD11: =AVERAGE(T11,AH11,AV11,BJ11,BX11,CL11,CZ11,DN11,EB11,EP11) -> 419.8 | FE11: =AVERAGE(U11,AI11,AW11,BK11,BY11,CM11,DA11,DO11,EC11,EQ11) -> 123.9 | FF11: =AVERAGE(V11,AJ11,AX11,BL11,BZ11,CN11,DB11,DP11,ED11,ER11) -> 295.9 | FG11: =IF(AND(FC11=EO11,FC11=EA11,FC11=DM11,FC11=CY11,FC11=CK11,FC11=BW11,FC11=BI11,FC11=AU11,FC11=AG11),"equal","no equal") -> equal | FH11: =AVERAGE(Z11,AN11,BB11,BP11,CD11,CR11,DF11,DT11,EH11,EV11) -> 126 | FI11: =AVERAGE(W11,AK11,AY11,BM11,CA11,CO11,DC11,DQ11,EE11,ES11) -> 274.7 | FJ11: =AVERAGE(AA11,AO11,BC11,BQ11,CE11,CS11,DG11,DU11,EI11,EW11) -> 14.8 | FK11: =AVERAGE(X11,AL11,AZ11,BN11,CB11,CP11,DD11,DR11,EF11,ET11) -> 87 | FL11: =AVERAGE(AD11,AR11,BF11,BT11,CH11,CV11,DJ11,DX11,EL11,EZ11) -> 76 | FM11: =AVERAGE(AC11,AQ11,BE11,BS11,CG11,CU11,DI11,DW11,EK11,EY11) -> 17.8 | FN11: =AVERAGE(AB11,AP11,BD11,BR11,CF11,CT11,DH11,DV11,EJ11,EX11) -> 13.4
FC12: Total: | FD12: =AVERAGE(FD5:FD11) -> 722.05714 | FE12: =AVERAGE(FE5:FE11) -> 213.18571 | FF12: =AVERAGE(FF5:FF11) -> 508.87143 | FG12: equal | FH12: =AVERAGE(FH5:FH11) -> 197.32857 | FI12: =AVERAGE(FI5:FI11) -> 377.35714 | FJ12: =AVERAGE(FJ5:FJ11) -> 146.18571 | FK12: =AVERAGE(FK5:FK11) -> 142.65714 | FL12: =AVERAGE(FL5:FL11) -> 82.7 | FM12: =AVERAGE(FM5:FM11) -> 18.757143 | FN12: =AVERAGE(FN5:FN11) -> 15.814286

Sheet Execution-time results
A1: Application | B1: Mean time | C1: MIN | D1: MAX | E1: Mean audit | F1: Mean compile | G1: SD (min) | H1: CV (%)
A2: =Datas!A5 -> Signal Android | B2: =Datas!FD5/60 -> 29.826667 | C2: =MIN(Datas!T5,Datas!AH5,Datas!AV5,Datas!BJ4,Datas!BX5,Datas!CL5,Datas!CZ5,Datas!DN5,Datas!EB5,Datas!EP5)/60 -> 25.916667 | D2: =MAX(Datas!T5,Datas!AH5,Datas!AV5,Datas!BJ4,Datas!BX5,Datas!CL5,Datas!CZ5,Datas!DN5,Datas!EB5,Datas!EP5)/60 -> 35.733333 | E2: =Datas!FF5/60 -> 20.05 | F2: =Datas!FE5/60 -> 9.7766667 | G2: =_xlfn.STDEV.S(Datas!T5,Datas!AH5,Datas!AV5,Datas!BJ4,Datas!BX5,Datas!CL5,Datas!CZ5,Datas!DN5,Datas!EB5,Datas!EP5)/60 -> 4.1751312 | H2: =G2/(B2)*100 -> 13.997981
A3: =Datas!A6 -> K-9 Mail (Thunderbird Android) | B3: =Datas!FD6/60 -> 14.74 | C3: =MIN(Datas!T6,Datas!AH6,Datas!AV6,Datas!BJ5,Datas!BX6,Datas!CL6,Datas!CZ6,Datas!DN6,Datas!EB6,Datas!EP6)/60 -> 14 | D3: =MAX(Datas!T6,Datas!AH6,Datas!AV6,Datas!BJ5,Datas!BX6,Datas!CL6,Datas!CZ6,Datas!DN6,Datas!EB6,Datas!EP6)/60 -> 38.133333 | E3: =Datas!FF6/60 -> 12.016667 | F3: =Datas!FE6/60 -> 2.7233333 | G3: =_xlfn.STDEV.S(Datas!T6,Datas!AH6,Datas!AV6,Datas!BJ5,Datas!BX6,Datas!CL6,Datas!CZ6,Datas!DN6,Datas!EB6,Datas!EP6)/60 -> 7.4299453 | H3: =G3/(B3)*100 -> 50.406684
A4: =Datas!A7 -> AntennaPod | B4: =Datas!FD7/60 -> 9.5933333 | C4: =MIN(Datas!T7,Datas!AH7,Datas!AV7,Datas!BJ6,Datas!BX7,Datas!CL7,Datas!CZ7,Datas!DN7,Datas!EB7,Datas!EP7)/60 -> 9.2 | D4: =MAX(Datas!T7,Datas!AH7,Datas!AV7,Datas!BJ6,Datas!BX7,Datas!CL7,Datas!CZ7,Datas!DN7,Datas!EB7,Datas!EP7)/60 -> 15.433333 | E4: =Datas!FF7/60 -> 4.9266667 | F4: =Datas!FE7/60 -> 4.6666667 | G4: =_xlfn.STDEV.S(Datas!T7,Datas!AH7,Datas!AV7,Datas!BJ6,Datas!BX7,Datas!CL7,Datas!CZ7,Datas!DN7,Datas!EB7,Datas!EP7)/60 -> 1.8855395 | H4: =G4/(B4)*100 -> 19.654686
A5: =Datas!A8 -> Markor | B5: =Datas!FD8/60 -> 7.2866667 | C5: =MIN(Datas!T8,Datas!AH8,Datas!AV8,Datas!BJ7,Datas!BX8,Datas!CL8,Datas!CZ8,Datas!DN8,Datas!EB8,Datas!EP8)/60 -> 6.4666667 | D5: =MAX(Datas!T8,Datas!AH8,Datas!AV8,Datas!BJ7,Datas!BX8,Datas!CL8,Datas!CZ8,Datas!DN8,Datas!EB8,Datas!EP8)/60 -> 9.4 | E5: =Datas!FF8/60 -> 5 | F5: =Datas!FE8/60 -> 2.2866667 | G5: =_xlfn.STDEV.S(Datas!T8,Datas!AH8,Datas!AV8,Datas!BJ7,Datas!BX8,Datas!CL8,Datas!CZ8,Datas!DN8,Datas!EB8,Datas!EP8)/60 -> 1.0037292 | H5: =G5/(B5)*100 -> 13.774874
A6: =Datas!A9 -> Fdroidclient | B6: =Datas!FD9/60 -> 9.015 | C6: =MIN(Datas!T9,Datas!AH9,Datas!AV9,Datas!BJ8,Datas!BX9,Datas!CL9,Datas!CZ9,Datas!DN9,Datas!EB9,Datas!EP9)/60 -> 7.05 | D6: =MAX(Datas!T9,Datas!AH9,Datas!AV9,Datas!BJ8,Datas!BX9,Datas!CL9,Datas!CZ9,Datas!DN9,Datas!EB9,Datas!EP9)/60 -> 11.416667 | E6: =Datas!FF9/60 -> 6.27 | F6: =Datas!FE9/60 -> 2.745 | G6: =_xlfn.STDEV.S(Datas!T9,Datas!AH9,Datas!AV9,Datas!BJ8,Datas!BX9,Datas!CL9,Datas!CZ9,Datas!DN9,Datas!EB9,Datas!EP9)/60 -> 1.4893656 | H6: =G6/(B6)*100 -> 16.520972
A7: =Datas!A10 -> Damn-Vulnerable-Android-Components | B7: =Datas!FD10/60 -> 6.7816667 | C7: =MIN(Datas!T10,Datas!AH10,Datas!AV10,Datas!BJ9,Datas!BX10,Datas!CL10,Datas!CZ10,Datas!DN10,Datas!EB10,Datas!EP10)/60 -> 6.2 | D7: =MAX(Datas!T10,Datas!AH10,Datas!AV10,Datas!BJ9,Datas!BX10,Datas!CL10,Datas!CZ10,Datas!DN10,Datas!EB10,Datas!EP10)/60 -> 10.2 | E7: =Datas!FF10/60 -> 6.1733333 | F7: =Datas!FE10/60 -> 0.60833333 | G7: =_xlfn.STDEV.S(Datas!T10,Datas!AH10,Datas!AV10,Datas!BJ9,Datas!BX10,Datas!CL10,Datas!CZ10,Datas!DN10,Datas!EB10,Datas!EP10)/60 -> 1.1435217 | H7: =G7/(B7)*100 -> 16.861957
A8: =Datas!A11 -> OpenMRS | B8: =Datas!FD11/60 -> 6.9966667 | C8: =MIN(Datas!T11,Datas!AH11,Datas!AV11,Datas!BJ10,Datas!BX11,Datas!CL11,Datas!CZ11,Datas!DN11,Datas!EB11,Datas!EP11)/60 -> 6.4166667 | D8: =MAX(Datas!T11,Datas!AH11,Datas!AV11,Datas!BJ10,Datas!BX11,Datas!CL11,Datas!CZ11,Datas!DN11,Datas!EB11,Datas!EP11)/60 -> 8.3166667 | E8: =Datas!FF11/60 -> 4.9316667 | F8: =Datas!FE11/60 -> 2.065 | G8: =_xlfn.STDEV.S(Datas!T11,Datas!AH11,Datas!AV11,Datas!BJ10,Datas!BX11,Datas!CL11,Datas!CZ11,Datas!DN11,Datas!EB11,Datas!EP11)/60 -> 0.53559993 | H8: =G8/(B8)*100 -> 7.6550728

Sheet Runtime by pipeline operation
A1: Application | B1: Mean time
A2: MobSF | B2: =Datas!FH12 -> 197.32857
A3: CodeQL | B3: =Datas!FI12 -> 377.35714
A4: Compile | B4: =Datas!FE12 -> 213.18571
A5: Vision360 | B5: =Datas!FJ12 -> 146.18571
A6: Trivy | B6: =Datas!FK12 -> 142.65714
A7: Final summary | B7: =Datas!FL12 -> 82.7
A8: JSON output | B8: =Datas!FM12 -> 18.757143
A9: Req. Evaluation | B9: =Datas!FN12 -> 15.814286

Sheet Scalability indicators
A1: Application | B1: Mean time | C1: Respository size
A2: =Datas!A5 -> Signal Android | B2: =Datas!FD5/60 -> 29.826667 | C2: =Datas!G5 -> 2360
A3: =Datas!A6 -> K-9 Mail (Thunderbird Android) | B3: =Datas!FD6/60 -> 14.74 | C3: =Datas!G6 -> 248
A4: =Datas!A7 -> AntennaPod | B4: =Datas!FD7/60 -> 9.5933333 | C4: =Datas!G7 -> 134
A5: =Datas!A8 -> Markor | B5: =Datas!FD8/60 -> 7.2866667 | C5: =Datas!G8 -> 58.2
A6: =Datas!A9 -> Fdroidclient | B6: =Datas!FD9/60 -> 9.015 | C6: =Datas!G9 -> 79.7
A7: =Datas!A10 -> Damn-Vulnerable-Android-Components | B7: =Datas!FD10/60 -> 6.7816667 | C7: =Datas!G10 -> 37.3
A8: =Datas!A11 -> OpenMRS | B8: =Datas!FD11/60 -> 6.9966667 | C8: =Datas!G11 -> 12.1

Sheet Runtime distribution
A1: Application | B1: Total | C1: Parallel (CodeQL, Trivy, MobSF, zipped code) (%) | D1: Vision360 (%) | E1: Requirement evaluation (%) | F1: JSON generation (%) | G1: Final summary (%) | H1: Others (%)
A2: =Datas!A5 -> Signal Android | B2: =Datas!FD5/60 -> 29.826667 | C2: =(MAX(Datas!FI5,Datas!FK5,(Datas!FE5+Datas!FH5))/60)/$B2*100 -> 64.159589 | D2: =(Datas!FJ5/60)/$B2*100 -> 28.257711 | E2: =(Datas!FN5/60)/$B2*100 -> 0.97787215 | F2: =(Datas!FM5/60)/$B2*100 -> 1.0728654 | G2: =(Datas!FL5/60)/$B2*100 -> 4.4143943 | H2: =100-SUM(C2:G2) -> 1.1175682
A3: =Datas!A6 -> K-9 Mail (Thunderbird Android) | B3: =Datas!FD6/60 -> 14.74 | C3: =(MAX(Datas!FI6,Datas!FK6,(Datas!FE6+Datas!FH6))/60)/$B3*100 -> 37.833559 | D3: =(Datas!FJ6/60)/$B3*100 -> 46.359114 | E3: =(Datas!FN6/60)/$B3*100 -> 2.125735 | F3: =(Datas!FM6/60)/$B3*100 -> 2.1709634 | G3: =(Datas!FL6/60)/$B3*100 -> 9.2265943 | H3: =100-SUM(C3:G3) -> 2.2840344
A4: =Datas!A7 -> AntennaPod | B4: =Datas!FD7/60 -> 9.5933333 | C4: =(MAX(Datas!FI7,Datas!FK7,(Datas!FE7+Datas!FH7))/60)/$B4*100 -> 72.168172 | D4: =(Datas!FJ7/60)/$B4*100 -> 4.5691452 | E4: =(Datas!FN7/60)/$B4*100 -> 2.5538568 | F4: =(Datas!FM7/60)/$B4*100 -> 3.3877693 | G4: =(Datas!FL7/60)/$B4*100 -> 13.603197 | H4: =100-SUM(C4:G4) -> 3.7178596
A5: =Datas!A8 -> Markor | B5: =Datas!FD8/60 -> 7.2866667 | C5: =(MAX(Datas!FI8,Datas!FK8,(Datas!FE8+Datas!FH8))/60)/$B5*100 -> 60.178408 | D5: =(Datas!FJ8/60)/$B5*100 -> 4.4373285 | E5: =(Datas!FN8/60)/$B5*100 -> 3.5452882 | F5: =(Datas!FM8/60)/$B5*100 -> 4.36871 | G5: =(Datas!FL8/60)/$B5*100 -> 21.317475 | H5: =100-SUM(C5:G5) -> 6.1527905
A6: =Datas!A9 -> Fdroidclient | B6: =Datas!FD9/60 -> 9.015 | C6: =(MAX(Datas!FI9,Datas!FK9,(Datas!FE9+Datas!FH9))/60)/$B6*100 -> 64.207802 | D6: =(Datas!FJ9/60)/$B6*100 -> 6.9513773 | E6: =(Datas!FN9/60)/$B6*100 -> 2.8840821 | F6: =(Datas!FM9/60)/$B6*100 -> 3.5496395 | G6: =(Datas!FL9/60)/$B6*100 -> 16.43557 | H6: =100-SUM(C6:G6) -> 5.9715289
A7: =Datas!A10 -> Damn-Vulnerable-Android-Components | B7: =Datas!FD10/60 -> 6.7816667 | C7: =(MAX(Datas!FI10,Datas!FK10,(Datas!FE10+Datas!FH10))/60)/$B7*100 -> 64.217252 | D7: =(Datas!FJ10/60)/$B7*100 -> 2.334726 | E7: =(Datas!FN10/60)/$B7*100 -> 3.7355616 | F7: =(Datas!FM10/60)/$B7*100 -> 4.2516589 | G7: =(Datas!FL10/60)/$B7*100 -> 20.127796 | H7: =100-SUM(C7:G7) -> 5.3330057
A8: =Datas!A11 -> OpenMRS | B8: =Datas!FD11/60 -> 6.9966667 | C8: =(MAX(Datas!FI11,Datas!FK11,(Datas!FE11+Datas!FH11))/60)/$B8*100 -> 65.435922 | D8: =(Datas!FJ11/60)/$B8*100 -> 3.5254883 | E8: =(Datas!FN11/60)/$B8*100 -> 3.1919962 | F8: =(Datas!FM11/60)/$B8*100 -> 4.2401143 | G8: =(Datas!FL11/60)/$B8*100 -> 18.103859 | H8: =100-SUM(C8:G8) -> 5.5026203

Sheet Strongest associations wth time
A1: UFP (Unadjusted Function Points)
A2: Application | B2: Mean time | C2: UFP | D2: Rank repository | E2: Rank time
A3: =Datas!A5 -> Signal Android | B3: =Datas!FD5 -> 1789.6 | C3: =Datas!S5 -> 12500 | D3: =_xlfn.RANK.AVG(C3,$C$3:$C$9,1) -> 7 | E3: =_xlfn.RANK.AVG(B3,$B$3:$B$9,1) -> 7
A4: =Datas!A6 -> K-9 Mail (Thunderbird Android) | B4: =Datas!FD6 -> 884.4 | C4: =Datas!S6 -> 1183 | D4: =_xlfn.RANK.AVG(C4,$C$3:$C$9,1) -> 6 | E4: =_xlfn.RANK.AVG(B4,$B$3:$B$9,1) -> 6
A5: =Datas!A7 -> AntennaPod | B5: =Datas!FD7 -> 575.6 | C5: =Datas!S7 -> 1180 | D5: =_xlfn.RANK.AVG(C5,$C$3:$C$9,1) -> 5 | E5: =_xlfn.RANK.AVG(B5,$B$3:$B$9,1) -> 5
A6: =Datas!A8 -> Markor | B6: =Datas!FD8 -> 437.2 | C6: =Datas!S8 -> 576 | D6: =_xlfn.RANK.AVG(C6,$C$3:$C$9,1) -> 3 | E6: =_xlfn.RANK.AVG(B6,$B$3:$B$9,1) -> 3
A7: =Datas!A9 -> Fdroidclient | B7: =Datas!FD9 -> 540.9 | C7: =Datas!S9 -> 716 | D7: =_xlfn.RANK.AVG(C7,$C$3:$C$9,1) -> 4 | E7: =_xlfn.RANK.AVG(B7,$B$3:$B$9,1) -> 4
A8: =Datas!A10 -> Damn-Vulnerable-Android-Components | B8: =Datas!FD10 -> 406.9 | C8: =Datas!S10 -> 79 | D8: =_xlfn.RANK.AVG(C8,$C$3:$C$9,1) -> 1 | E8: =_xlfn.RANK.AVG(B8,$B$3:$B$9,1) -> 1
A9: =Datas!A11 -> OpenMRS | B9: =Datas!FD11 -> 419.8 | C9: =Datas!S11 -> 462 | D9: =_xlfn.RANK.AVG(C9,$C$3:$C$9,1) -> 2 | E9: =_xlfn.RANK.AVG(B9,$B$3:$B$9,1) -> 2
A11: Spearman ρ: | B11: =IF(ABS(B12)=1,"<0.001",_xlfn.T.DIST.2T(ABS(B12*SQRT((7-2)/(1-B12^2))),7-2)) -> <0.001
A12: Spearman rho: | B12: =CORREL(D3:D9,E3:E9) -> 1
A21: Repository Size (MB)
A22: Application | B22: Mean time | C22: Repository size | D22: Rank repository | E22: Rank time
A23: =Datas!A5 -> Signal Android | B23: =Datas!FD5 -> 1789.6 | C23: =Datas!G5 -> 2360 | D23: =_xlfn.RANK.AVG(C23,$C$23:$C$29,1) -> 7 | E23: =_xlfn.RANK.AVG(B23,$B$23:$B$29,1) -> 7
A24: =Datas!A6 -> K-9 Mail (Thunderbird Android) | B24: =Datas!FD6 -> 884.4 | C24: =Datas!G6 -> 248 | D24: =_xlfn.RANK.AVG(C24,$C$23:$C$29,1) -> 6 | E24: =_xlfn.RANK.AVG(B24,$B$23:$B$29,1) -> 6
A25: =Datas!A7 -> AntennaPod | B25: =Datas!FD7 -> 575.6 | C25: =Datas!G7 -> 134 | D25: =_xlfn.RANK.AVG(C25,$C$23:$C$29,1) -> 5 | E25: =_xlfn.RANK.AVG(B25,$B$23:$B$29,1) -> 5
A26: =Datas!A8 -> Markor | B26: =Datas!FD8 -> 437.2 | C26: =Datas!G8 -> 58.2 | D26: =_xlfn.RANK.AVG(C26,$C$23:$C$29,1) -> 3 | E26: =_xlfn.RANK.AVG(B26,$B$23:$B$29,1) -> 3
A27: =Datas!A9 -> Fdroidclient | B27: =Datas!FD9 -> 540.9 | C27: =Datas!G9 -> 79.7 | D27: =_xlfn.RANK.AVG(C27,$C$23:$C$29,1) -> 4 | E27: =_xlfn.RANK.AVG(B27,$B$23:$B$29,1) -> 4
A28: =Datas!A10 -> Damn-Vulnerable-Android-Components | B28: =Datas!FD10 -> 406.9 | C28: =Datas!G10 -> 37.3 | D28: =_xlfn.RANK.AVG(C28,$C$23:$C$29,1) -> 2 | E28: =_xlfn.RANK.AVG(B28,$B$23:$B$29,1) -> 1
A29: =Datas!A11 -> OpenMRS | B29: =Datas!FD11 -> 419.8 | C29: =Datas!G11 -> 12.1 | D29: =_xlfn.RANK.AVG(C29,$C$23:$C$29,1) -> 1 | E29: =_xlfn.RANK.AVG(B29,$B$23:$B$29,1) -> 2
A31: Spearman ρ: | B31: =IF(ABS(B32)=1,"<0.001",_xlfn.T.DIST.2T(ABS(B32*SQRT((7-2)/(1-B32^2))),7-2)) -> 0.00045414917
A32: Spearman rho: | B32: =CORREL(D23:D29,E23:E29) -> 0.96428571
A41: Total Findings
A42: Application | B42: Mean time | C42: Total Files Scanned | D42: Rank repository | E42: Rank time
A43: =Datas!A5 -> Signal Android | B43: =Datas!FD5 -> 1789.6 | C43: =Datas!K5 -> 8737 | D43: =_xlfn.RANK.AVG(C43,$C$43:$C$49,1) -> 7 | E43: =_xlfn.RANK.AVG(B43,$B$43:$B$49,1) -> 7
A44: =Datas!A6 -> K-9 Mail (Thunderbird Android) | B44: =Datas!FD6 -> 884.4 | C44: =Datas!K6 -> 7139 | D44: =_xlfn.RANK.AVG(C44,$C$43:$C$49,1) -> 6 | E44: =_xlfn.RANK.AVG(B44,$B$43:$B$49,1) -> 6
A45: =Datas!A7 -> AntennaPod | B45: =Datas!FD7 -> 575.6 | C45: =Datas!K7 -> 1165 | D45: =_xlfn.RANK.AVG(C45,$C$43:$C$49,1) -> 4 | E45: =_xlfn.RANK.AVG(B45,$B$43:$B$49,1) -> 5
A46: =Datas!A8 -> Markor | B46: =Datas!FD8 -> 437.2 | C46: =Datas!K8 -> 797 | D46: =_xlfn.RANK.AVG(C46,$C$43:$C$49,1) -> 2 | E46: =_xlfn.RANK.AVG(B46,$B$43:$B$49,1) -> 3
A47: =Datas!A9 -> Fdroidclient | B47: =Datas!FD9 -> 540.9 | C47: =Datas!K9 -> 2086 | D47: =_xlfn.RANK.AVG(C47,$C$43:$C$49,1) -> 5 | E47: =_xlfn.RANK.AVG(B47,$B$43:$B$49,1) -> 4
A48: =Datas!A10 -> Damn-Vulnerable-Android-Components | B48: =Datas!FD10 -> 406.9 | C48: =Datas!K10 -> 120 | D48: =_xlfn.RANK.AVG(C48,$C$43:$C$49,1) -> 1 | E48: =_xlfn.RANK.AVG(B48,$B$43:$B$49,1) -> 1
A49: =Datas!A11 -> OpenMRS | B49: =Datas!FD11 -> 419.8 | C49: =Datas!K11 -> 839 | D49: =_xlfn.RANK.AVG(C49,$C$43:$C$49,1) -> 3 | E49: =_xlfn.RANK.AVG(B49,$B$43:$B$49,1) -> 2
A51: Spearman ρ: | B51: =IF(ABS(B52)=1,"<0.001",_xlfn.T.DIST.2T(ABS(B52*SQRT((7-2)/(1-B52^2))),7-2)) -> 0.0025194724
A52: Spearman rho: | B52: =CORREL(D43:D49,E43:E49) -> 0.92857143
A62: CodeQL Findings
A63: Application | B63: Mean time | C63: CodeQL Findings | D63: Rank repository | E63: Rank time
A64: =Datas!A5 -> Signal Android | B64: =Datas!FD5 -> 1789.6 | C64: =Datas!M5 -> 1877 | D64: =_xlfn.RANK.AVG(C64,$C$64:$C$70,1) -> 7 | E64: =_xlfn.RANK.AVG(B64,$B$64:$B$70,1) -> 7
A65: =Datas!A6 -> K-9 Mail (Thunderbird Android) | B65: =Datas!FD6 -> 884.4 | C65: =Datas!M6 -> 295 | D65: =_xlfn.RANK.AVG(C65,$C$64:$C$70,1) -> 5 | E65: =_xlfn.RANK.AVG(B65,$B$64:$B$70,1) -> 6
A66: =Datas!A7 -> AntennaPod | B66: =Datas!FD7 -> 575.6 | C66: =Datas!M7 -> 619 | D66: =_xlfn.RANK.AVG(C66,$C$64:$C$70,1) -> 6 | E66: =_xlfn.RANK.AVG(B66,$B$64:$B$70,1) -> 5
A67: =Datas!A8 -> Markor | B67: =Datas!FD8 -> 437.2 | C67: =Datas!M8 -> 158 | D67: =_xlfn.RANK.AVG(C67,$C$64:$C$70,1) -> 3 | E67: =_xlfn.RANK.AVG(B67,$B$64:$B$70,1) -> 3
A68: =Datas!A9 -> Fdroidclient | B68: =Datas!FD9 -> 540.9 | C68: =Datas!M9 -> 235 | D68: =_xlfn.RANK.AVG(C68,$C$64:$C$70,1) -> 4 | E68: =_xlfn.RANK.AVG(B68,$B$64:$B$70,1) -> 4
...

Sheet Exploratory models
A1: Application | B1: Mean time | C1: Respository size | D1: Predicted time | E1: Error | F1: Error^2 | G1: Total variance component | H1: LOOCV predicted time | I1: Absolute error | L1: =AVERAGE(B2:B8) -> 12.034286
A2: =Datas!A5 -> Signal Android | B2: =Datas!FD5/60 -> 29.826667 | C2: =Datas!G5 -> 2360 | D2: =2.477*(C2^0.307) -> 26.878807 | E2: =B2-D2 -> 2.9478595 | F2: =E2^2 -> 8.6898757 | G2: =(B2-$L$1)^2 -> 316.56882 | H2: {=_xlfn.LET(_xlpm.y,_xlfn._xlws.FILTER(LN($B$2:$B$8),$A$2:$A$8<>A2),_xlpm.x,_xlfn._xlws.FILTER(LN($C$2:$C$8),$A$2:$A$8<>A2),_xlpm.a,INTERCEPT(_xlpm.y,_xlpm.x),_xlpm.b,SLOPE(_xlpm.y,_xlpm.x),EXP(_xlpm.a+_xlpm.b*LN(C2)))} -> 20.556055 | I2: =ABS(B2-H2) -> 9.2706119
A3: =Datas!A6 -> K-9 Mail (Thunderbird Android) | B3: =Datas!FD6/60 -> 14.74 | C3: =Datas!G6 -> 248 | D3: =2.477*(C3^0.307) -> 13.459306 | E3: =B3-D3 -> 1.2806938 | F3: =E3^2 -> 1.6401767 | G3: =(B3-$L$1)^2 -> 7.3208898 | H3: {=_xlfn.LET(_xlpm.y,_xlfn._xlws.FILTER(LN($B$2:$B$8),$A$2:$A$8<>A3),_xlpm.x,_xlfn._xlws.FILTER(LN($C$2:$C$8),$A$2:$A$8<>A3),_xlpm.a,INTERCEPT(_xlpm.y,_xlpm.x),_xlpm.b,SLOPE(_xlpm.y,_xlpm.x),EXP(_xlpm.a+_xlpm.b*LN(C3)))} -> 13.167357 | I3: =ABS(B3-H3) -> 1.5726433 | L3: R^2: | M3: =1-SUM(F2:F8)/SUM(G2:G8) -> 0.95633766
A4: =Datas!A7 -> AntennaPod | B4: =Datas!FD7/60 -> 9.5933333 | C4: =Datas!G7 -> 134 | D4: =2.477*(C4^0.307) -> 11.14159 | E4: =B4-D4 -> -1.5482568 | F4: =E4^2 -> 2.3970993 | G4: =(B4-$L$1)^2 -> 5.9582485 | H4: {=_xlfn.LET(_xlpm.y,_xlfn._xlws.FILTER(LN($B$2:$B$8),$A$2:$A$8<>A4),_xlpm.x,_xlfn._xlws.FILTER(LN($C$2:$C$8),$A$2:$A$8<>A4),_xlpm.a,INTERCEPT(_xlpm.y,_xlpm.x),_xlpm.b,SLOPE(_xlpm.y,_xlpm.x),EXP(_xlpm.a+_xlpm.b*LN(C4)))} -> 11.417011 | I4: =ABS(B4-H4) -> 1.8236777 | L4: LOOCV MAE: | M4: =AVERAGE(I2:I8) -> 2.6370351
A5: =Datas!A8 -> Markor | B5: =Datas!FD8/60 -> 7.2866667 | C5: =Datas!G8 -> 58.2 | D5: =2.477*(C5^0.307) -> 8.6249654 | E5: =B5-D5 -> -1.3382988 | F5: =E5^2 -> 1.7910436 | G5: =(B5-$L$1)^2 -> 22.539887 | H5: {=_xlfn.LET(_xlpm.y,_xlfn._xlws.FILTER(LN($B$2:$B$8),$A$2:$A$8<>A5),_xlpm.x,_xlfn._xlws.FILTER(LN($C$2:$C$8),$A$2:$A$8<>A5),_xlpm.a,INTERCEPT(_xlpm.y,_xlpm.x),_xlpm.b,SLOPE(_xlpm.y,_xlpm.x),EXP(_xlpm.a+_xlpm.b*LN(C5)))} -> 8.9092228 | I5: =ABS(B5-H5) -> 1.6225561
A6: =Datas!A9 -> Fdroidclient | B6: =Datas!FD9/60 -> 9.015 | C6: =Datas!G9 -> 79.7 | D6: =2.477*(C6^0.307) -> 9.4989087 | E6: =B6-D6 -> -0.48390865 | F6: =E6^2 -> 0.23416758 | G6: =(B6-$L$1)^2 -> 9.1160862 | H6: {=_xlfn.LET(_xlpm.y,_xlfn._xlws.FILTER(LN($B$2:$B$8),$A$2:$A$8<>A6),_xlpm.x,_xlfn._xlws.FILTER(LN($C$2:$C$8),$A$2:$A$8<>A6),_xlpm.a,INTERCEPT(_xlpm.y,_xlpm.x),_xlpm.b,SLOPE(_xlpm.y,_xlpm.x),EXP(_xlpm.a+_xlpm.b*LN(C6)))} -> 9.5759036 | I6: =ABS(B6-H6) -> 0.56090363
A7: =Datas!A10 -> Damn-Vulnerable-Android-Components | B7: =Datas!FD10/60 -> 6.7816667 | C7: =Datas!G10 -> 37.3 | D7: =2.477*(C7^0.307) -> 7.5238585 | E7: =B7-D7 -> -0.74219181 | F7: =E7^2 -> 0.55084868 | G7: =(B7-$L$1)^2 -> 27.590007 | H7: {=_xlfn.LET(_xlpm.y,_xlfn._xlws.FILTER(LN($B$2:$B$8),$A$2:$A$8<>A7),_xlpm.x,_xlfn._xlws.FILTER(LN($C$2:$C$8),$A$2:$A$8<>A7),_xlpm.a,INTERCEPT(_xlpm.y,_xlpm.x),_xlpm.b,SLOPE(_xlpm.y,_xlpm.x),EXP(_xlpm.a+_xlpm.b*LN(C7)))} -> 7.7271381 | I7: =ABS(B7-H7) -> 0.9454714
A8: =Datas!A11 -> OpenMRS | B8: =Datas!FD11/60 -> 6.9966667 | C8: =Datas!G11 -> 12.1 | D8: =2.477*(C8^0.307) -> 5.3252637 | E8: =B8-D8 -> 1.671403 | F8: =E8^2 -> 2.793588 | G8: =(B8-$L$1)^2 -> 25.377606 | H8: {=_xlfn.LET(_xlpm.y,_xlfn._xlws.FILTER(LN($B$2:$B$8),$A$2:$A$8<>A8),_xlpm.x,_xlfn._xlws.FILTER(LN($C$2:$C$8),$A$2:$A$8<>A8),_xlpm.a,INTERCEPT(_xlpm.y,_xlpm.x),_xlpm.b,SLOPE(_xlpm.y,_xlpm.x),EXP(_xlpm.a+_xlpm.b*LN(C8)))} -> 4.3332852 | I8: =ABS(B8-H8) -> 2.6633815
A16: Application | B16: Mean time | C16: LOC | D16: Total scanned files | E16: Predicted time | F16: Error | G16: Error^2 | H16: Total variance component | I16: LOOCV predicted time | J16: Absolute error | L16: =AVERAGE(B17:B23) -> 12.034286
A17: =Datas!A5 -> Signal Android | B17: =Datas!FD5/60 -> 29.826667 | C17: =Datas!L5 -> 1603006 | D17: =Datas!K5 -> 8737 | E17: =6.505+(0.00000919*C17)+(0.000983*D17) -> 29.825096 | F17: =B17-E17 -> 0.0015705267 | G17: =F17^2 -> 2.466554e-06 | H17: =(B17-$L$16)^2 -> 316.56882 | I17: {=_xlfn.LET(_xlpm.y,_xlfn._xlws.FILTER($B$17:$B$23,$A$17:$A$23<>A17),_xlpm.x,_xlfn._xlws.FILTER($C$17:$D$23,$A$17:$A$23<>A17),_xlpm.coef,LINEST(_xlpm.y,_xlpm.x,TRUE,FALSE),_xlpm.b_files,INDEX(_xlpm.coef,1,1),_xlpm.b_loc,INDEX(_xlpm.coef,1,2),_xlpm.intercept,INDEX(_xlpm.coef,1,3),_xlpm.intercept+(_xlpm.b_loc*C17)+(_xlpm.b_files*D17))} -> 28.095213 | J17: =ABS(B17-I17) -> 1.7314534
A18: =Datas!A6 -> K-9 Mail (Thunderbird Android) | B18: =Datas!FD6/60 -> 14.74 | C18: =Datas!L6 -> 129770 | D18: =Datas!K6 -> 7139 | E18: =6.505+(0.00000919*C18)+(0.000983*D18) -> 14.715223 | F18: =B18-E18 -> 0.0247767 | G18: =F18^2 -> 0.00061388486 | H18: =(B18-$L$16)^2 -> 7.3208898 | I18: {=_xlfn.LET(_xlpm.y,_xlfn._xlws.FILTER($B$17:$B$23,$A$17:$A$23<>A18),_xlpm.x,_xlfn._xlws.FILTER($C$17:$D$23,$A$17:$A$23<>A18),_xlpm.coef,LINEST(_xlpm.y,_xlpm.x,TRUE,FALSE),_xlpm.b_files,INDEX(_xlpm.coef,1,1),_xlpm.b_loc,INDEX(_xlpm.coef,1,2),_xlpm.intercept,INDEX(_xlpm.coef,1,3),_xlpm.intercept+(_xlpm.b_loc*C18)+(_xlpm.b_files*D18))} -> 14.134164 | J18: =ABS(B18-I18) -> 0.6058362 | L18: R^2: | M18: =1-SUM(G17:G23)/SUM(H17:H23) -> 0.99319691
A19: =Datas!A7 -> AntennaPod | B19: =Datas!FD7/60 -> 9.5933333 | C19: =Datas!L7 -> 62675 | D19: =Datas!K7 -> 1165 | E19: =6.505+(0.00000919*C19)+(0.000983*D19) -> 8.2261783 | F19: =B19-E19 -> 1.3671551 | G19: =F19^2 -> 1.869113 | H19: =(B19-$L$16)^2 -> 5.9582485 | I19: {=_xlfn.LET(_xlpm.y,_xlfn._xlws.FILTER($B$17:$B$23,$A$17:$A$23<>A19),_xlpm.x,_xlfn._xlws.FILTER($C$17:$D$23,$A$17:$A$23<>A19),_xlpm.coef,LINEST(_xlpm.y,_xlpm.x,TRUE,FALSE),_xlpm.b_files,INDEX(_xlpm.coef,1,1),_xlpm.b_loc,INDEX(_xlpm.coef,1,2),_xlpm.intercept,INDEX(_xlpm.coef,1,3),_xlpm.intercept+(_xlpm.b_loc*C19)+(_xlpm.b_files*D19))} -> 7.9082331 | J19: =ABS(B19-I19) -> 1.6851003 | L19: LOOCV MAE: | M19: =AVERAGE(J17:J23) -> 0.87117812
A20: =Datas!A8 -> Markor | B20: =Datas!FD8/60 -> 7.2866667 | C20: =Datas!L8 -> 30512 | D20: =Datas!K8 -> 797 | E20: =6.505+(0.00000919*C20)+(0.000983*D20) -> 7.5688563 | F20: =B20-E20 -> -0.28218961 | G20: =F20^2 -> 0.079630978 | H20: =(B20-$L$16)^2 -> 22.539887 | I20: {=_xlfn.LET(_xlpm.y,_xlfn._xlws.FILTER($B$17:$B$23,$A$17:$A$23<>A20),_xlpm.x,_xlfn._xlws.FILTER($C$17:$D$23,$A$17:$A$23<>A20),_xlpm.coef,LINEST(_xlpm.y,_xlpm.x,TRUE,FALSE),_xlpm.b_files,INDEX(_xlpm.coef,1,1),_xlpm.b_loc,INDEX(_xlpm.coef,1,2),_xlpm.intercept,INDEX(_xlpm.coef,1,3),_xlpm.intercept+(_xlpm.b_loc*C20)+(_xlpm.b_files*D20))} -> 7.644818 | J20: =ABS(B20-I20) -> 0.3581513
A21: =Datas!A9 -> Fdroidclient | B21: =Datas!FD9/60 -> 9.015 | C21: =Datas!L9 -> 94671 | D21: =Datas!K9 -> 2086 | E21: =6.505+(0.00000919*C21)+(0.000983*D21) -> 9.4255645 | F21: =B21-E21 -> -0.41056449 | G21: =F21^2 -> 0.1685632 | H21: =(B21-$L$16)^2 -> 9.1160862 | I21: {=_xlfn.LET(_xlpm.y,_xlfn._xlws.FILTER($B$17:$B$23,$A$17:$A$23<>A21),_xlpm.x,_xlfn._xlws.FILTER($C$17:$D$23,$A$17:$A$23<>A21),_xlpm.coef,LINEST(_xlpm.y,_xlpm.x,TRUE,FALSE),_xlpm.b_files,INDEX(_xlpm.coef,1,1),_xlpm.b_loc,INDEX(_xlpm.coef,1,2),_xlpm.intercept,INDEX(_xlpm.coef,1,3),_xlpm.intercept+(_xlpm.b_loc*C21)+(_xlpm.b_files*D21))} -> 9.5050675 | J21: =ABS(B21-I21) -> 0.49006747
A22: =Datas!A10 -> Damn-Vulnerable-Android-Components | B22: =Datas!FD10/60 -> 6.7816667 | C22: =Datas!L10 -> 2854 | D22: =Datas!K10 -> 120 | E22: =6.505+(0.00000919*C22)+(0.000983*D22) -> 6.6491883 | F22: =B22-E22 -> 0.13247841 | G22: =F22^2 -> 0.017550528 | H22: =(B22-$L$16)^2 -> 27.590007 | I22: {=_xlfn.LET(_xlpm.y,_xlfn._xlws.FILTER($B$17:$B$23,$A$17:$A$23<>A22),_xlpm.x,_xlfn._xlws.FILTER($C$17:$D$23,$A$17:$A$23<>A22),_xlpm.coef,LINEST(_xlpm.y,_xlpm.x,TRUE,FALSE),_xlpm.b_files,INDEX(_xlpm.coef,1,1),_xlpm.b_loc,INDEX(_xlpm.coef,1,2),_xlpm.intercept,INDEX(_xlpm.coef,1,3),_xlpm.intercept+(_xlpm.b_loc*C22)+(_xlpm.b_files*D22))} -> 6.6013782 | J22: =ABS(B22-I22) -> 0.18028844
A23: =Datas!A11 -> OpenMRS | B23: =Datas!FD11/60 -> 6.9966667 | C23: =Datas!L11 -> 53765 | D23: =Datas!K11 -> 839 | E23: =6.505+(0.00000919*C23)+(0.000983*D23) -> 7.8238373 | F23: =B23-E23 -> -0.82717068 | G23: =F23^2 -> 0.68421134 | H23: =(B23-$L$16)^2 -> 25.377606 | I23: {=_xlfn.LET(_xlpm.y,_xlfn._xlws.FILTER($B$17:$B$23,$A$17:$A$23<>A23),_xlpm.x,_xlfn._xlws.FILTER($C$17:$D$23,$A$17:$A$23<>A23),_xlpm.coef,LINEST(_xlpm.y,_xlpm.x,TRUE,FALSE),_xlpm.b_files,INDEX(_xlpm.coef,1,1),_xlpm.b_loc,INDEX(_xlpm.coef,1,2),_xlpm.intercept,INDEX(_xlpm.coef,1,3),_xlpm.intercept+(_xlpm.b_loc*C23)+(_xlpm.b_files*D23))} -> 8.0440164 | J23: =ABS(B23-I23) -> 1.0473498
